<?xml version="1.0"?>
<robot name="car" xmlns:xacro="http://www.ros.org/wiki/xacro">

  <!-- LINK: base_footprint -->
  <link name="base_footprint"></link>

  <!-- LINK: chassis -->
  <link name="chassis">
    <pose>0 0 0 0 0 0</pose>

    <inertial>
      <mass value="1000.0"/>
      <origin xyz="0.118 0 0" rpy="0 0 0"/>
      <inertia ixx="0.1" ixy="0" ixz="0" iyy="0.1" iyz="0" izz="0.1"/>
    </inertial>

    <collision name="chassis_collision">
      <origin xyz="0 0 0" rpy="0 0 0"/>
      <geometry>
        <mesh scale="0.001 0.001 0.001" filename="package://sim/meshes/chassis.stl"/>
      </geometry>
    </collision>

    <visual name="chassis_visual">
      <origin xyz="0 0 0" rpy="0 0 0"/>
      <geometry>
        <mesh scale="0.001 0.001 0.001" filename="package://sim/meshes/chassis.stl"/>
      </geometry>
    </visual>
  </link>

  <!-- LINK: main_steer -->
  <link name="main_steer">
    <pose>0 0 0 0 0 0</pose>

    <inertial>
      <mass value="1.0"/>
      <origin xyz="0 0 0" rpy="0 0 0"/>
      <inertia ixx="0.1" ixy="0" ixz="0" iyy="0.1" iyz="0" izz="0.1"/>
    </inertial>

    <collision name="main_steer_collision">
      <origin xyz="0 0 0" rpy="0 0 0"/>
      <geometry>
        <cylinder length="0.010" radius="0.010"/>
      </geometry>
    </collision>

    <visual name="main_steer_visual">
      <origin xyz="0 0 0" rpy="0 0 0"/>
      <geometry>
        <cylinder length="0.010" radius="0.010"/>
      </geometry>
    </visual>
  </link>

  <!-- LINK: left_steer -->
  <link name="left_steer">
    <pose>0 0 0 0 0 0</pose>

    <inertial>
      <mass value="1.0"/>
      <origin xyz="0 0 0" rpy="0 0 0"/>
      <inertia ixx="0.1" ixy="0" ixz="0" iyy="0.1" iyz="0" izz="0.1"/>
    </inertial>

    <collision name="left_steer_collision">
      <origin xyz="0 0 0" rpy="0 0 0"/>
      <geometry>
        <cylinder length="0.022" radius="0.002"/>
      </geometry>
    </collision>

    <visual name="left_steer_visual">
      <origin xyz="0 0 0" rpy="0 0 0"/>
      <geometry>
        <cylinder length="0.022" radius="0.002"/>
      </geometry>
    </visual>
  </link>

  <!-- LINK: right_steer -->
  <link name="right_steer">
    <pose>0 0 0 0 0 0</pose>

    <inertial>
      <mass value="1.0"/>
      <origin xyz="0 0 0" rpy="0 0 0"/>
      <inertia ixx="0.1" ixy="0" ixz="0" iyy="0.1" iyz="0" izz="0.1"/>
    </inertial>

    <collision name="right_steer_collision">
      <origin xyz="0 0 0" rpy="0 0 0"/>
      <geometry>
        <cylinder length="0.022" radius="0.002"/>
      </geometry>
    </collision>

    <visual name="right_steer_visual">
      <origin xyz="0 0 0" rpy="0 0 0"/>
      <geometry>
        <cylinder length="0.022" radius="0.002"/>
      </geometry>
    </visual>
  </link>

  <!-- LINK: rear_left_tire -->
  <link name="rear_left_tire">
    <pose>0 0 0 0 0 0</pose>

    <inertial>
      <mass value="50.0"/>
      <origin xyz="0 0 0" rpy="0 0 0"/>
      <inertia ixx="0.1" ixy="0" ixz="0" iyy="0.1" iyz="0" izz="0.1"/>
    </inertial>

    <collision name="rear_left_tire_collision">
      <origin xyz="0 0 0" rpy="0 0 0"/>
      <geometry>
        <cylinder length="0.026" radius="0.034"/>
      </geometry>
    </collision>

    <visual name="rear_left_tire_visual">
      <origin xyz="0 0 0" rpy="0 0 0"/>
      <geometry>
        <mesh scale="0.001 0.001 0.001" filename="package://sim/meshes/tire.stl"/>
      </geometry>
    </visual>
  </link>

  <!-- LINK: rear_left_disk -->
  <link name="rear_left_disk">
    <pose>0 0 0 0 0 0</pose>

    <collision name="rear_left_disk_collision">
      <origin xyz="0 0 0" rpy="0 0 0"/>
      <geometry>
        <mesh scale="0.001 0.001 0.001" filename="package://sim/meshes/disk.stl"/>
      </geometry>
    </collision>

    <visual name="rear_left_disk_visual">
      <origin xyz="0 0 0" rpy="0 0 0"/>
      <geometry>
        <mesh scale="0.001 0.001 0.001" filename="package://sim/meshes/disk.stl"/>
      </geometry>
    </visual>
  </link>

  <!-- LINK: rear_right_tire -->
  <link name="rear_right_tire">
    <pose>0 0 0 0 0 0</pose>

    <inertial>
      <mass value="50.0"/>
      <origin xyz="0 0 0" rpy="0 0 0"/>
      <inertia ixx="0.1" ixy="0" ixz="0" iyy="0.1" iyz="0" izz="0.1"/>
    </inertial>

    <collision name="rear_right_tire_collision">
      <origin xyz="0 0 0" rpy="0 0 0"/>
      <geometry>
        <cylinder length="0.026" radius="0.034"/>
      </geometry>
    </collision>

    <visual name="rear_right_tire_visual">
      <origin xyz="0 0 0" rpy="0 0 0"/>
      <geometry>
        <mesh scale="0.001 0.001 0.001" filename="package://sim/meshes/tire.stl"/>
      </geometry>
    </visual>
  </link>

  <!-- LINK: rear_right_disk -->
  <link name="rear_right_disk">
    <pose>0 0 0 0 0 0</pose>

    <collision name="rear_right_disk_collision">
      <origin xyz="0 0 0" rpy="0 0 0"/>
      <geometry>
        <mesh scale="0.001 0.001 0.001" filename="package://sim/meshes/disk.stl"/>
      </geometry>
    </collision>

    <visual name="rear_right_disk_visual">
      <origin xyz="0 0 0" rpy="0 0 0"/>
      <geometry>
        <mesh scale="0.001 0.001 0.001" filename="package://sim/meshes/disk.stl"/>
      </geometry>
    </visual>
  </link>

  <!-- LINK: front_left_tire -->
  <link name="front_left_tire">
    <pose>0 0 0 0 0 0</pose>

    <inertial>
      <mass value="50.0"/>
      <origin xyz="0 0 0" rpy="0 0 0"/>
      <inertia ixx="0.1" ixy="0" ixz="0" iyy="0.1" iyz="0" izz="0.1"/>
    </inertial>

    <collision name="front_left_tire_collision">
      <origin xyz="0 0 0" rpy="0 0 0"/>
      <geometry>
        <cylinder length="0.026" radius="0.034"/>
      </geometry>
    </collision>

    <visual name="front_left_tire_visual">
      <origin xyz="0 0 0" rpy="0 0 0"/>
      <geometry>
        <mesh scale="0.001 0.001 0.001" filename="package://sim/meshes/tire.stl"/>
      </geometry>
    </visual>
  </link>

  <!-- LINK: front_left_disk -->
  <link name="front_left_disk">
    <pose>0 0 0 0 0 0</pose>

    <collision name="front_left_disk_collision">
      <origin xyz="0 0 0" rpy="0 0 0"/>
      <geometry>
        <mesh scale="0.001 0.001 0.001" filename="package://sim/meshes/disk.stl"/>
      </geometry>
    </collision>

    <visual name="front_left_disk_visual">
      <origin xyz="0 0 0" rpy="0 0 0"/>
      <geometry>
        <mesh scale="0.001 0.001 0.001" filename="package://sim/meshes/disk.stl"/>
      </geometry>
    </visual>
  </link>

  <!-- LINK: front_right_tire -->
  <link name="front_right_tire">
    <pose>0 0 0 0 0 0</pose>

    <inertial>
      <mass value="50.0"/>
      <origin xyz="0 0 0" rpy="0 0 0"/>
      <inertia ixx="0.1" ixy="0" ixz="0" iyy="0.1" iyz="0" izz="0.1"/>
    </inertial>

    <collision name="front_right_tire_collision">
      <origin xyz="0 0 0" rpy="0 0 0"/>
      <geometry>
        <cylinder length="0.026" radius="0.034"/>
      </geometry>
    </collision>

    <visual name="front_right_tire_visual">
      <origin xyz="0 0 0" rpy="0 0 0"/>
      <geometry>
        <mesh scale="0.001 0.001 0.001" filename="package://sim/meshes/tire.stl"/>
      </geometry>
    </visual>
  </link>

  <!-- LINK: front_right_disk -->
  <link name="front_right_disk">
    <pose>0 0 0 0 0 0</pose>

    <collision name="front_right_disk_collision">
      <origin xyz="0 0 0" rpy="0 0 0"/>
      <geometry>
        <mesh scale="0.001 0.001 0.001" filename="package://sim/meshes/disk.stl"/>
      </geometry>
    </collision>

    <visual name="front_right_disk_visual">
      <origin xyz="0 0 0" rpy="0 0 0"/>
      <geometry>
        <mesh scale="0.001 0.001 0.001" filename="package://sim/meshes/disk.stl"/>
      </geometry>
    </visual>
  </link>

  <!-- COLOR: chassis -->
  <gazebo reference="chassis">
    <material>Gazebo/Grey</material>
  </gazebo>

  <!-- COLOR: main_steer -->
  <gazebo reference="main_steer">
    <material>Gazebo/Grey</material>
  </gazebo>

  <!-- COLOR: left_steer -->
  <gazebo reference="left_steer">
    <material>Gazebo/Grey</material>
  </gazebo>

  <!-- COLOR: right_steer -->
  <gazebo reference="right_steer">
    <material>Gazebo/Grey</material>
  </gazebo>

  <!-- COLOR: rear_left_tire -->
  <gazebo reference="rear_left_tire">
    <material>Gazebo/DarkGrey</material>
  </gazebo>

  <!-- COLOR: rear_left_disk -->
  <gazebo reference="rear_left_disk">
    <material>Gazebo/Grey</material>
  </gazebo>

  <!-- COLOR: rear_right_tire -->
  <gazebo reference="rear_right_tire">
    <material>Gazebo/DarkGrey</material>
  </gazebo>

  <!-- COLOR: rear_right_disk -->
  <gazebo reference="rear_right_disk">
    <material>Gazebo/Grey</material>
  </gazebo>

  <!-- COLOR: front_left_tire -->
  <gazebo reference="front_left_tire">
    <material>Gazebo/DarkGrey</material>
  </gazebo>

  <!-- COLOR: front_left_disk -->
  <gazebo reference="front_left_disk">
    <material>Gazebo/Grey</material>
  </gazebo>

  <!-- COLOR: front_right_tire -->
  <gazebo reference="front_right_tire">
    <material>Gazebo/DarkGrey</material>
  </gazebo>

  <!-- COLOR: front_right_disk -->
  <gazebo reference="front_right_disk">
    <material>Gazebo/Grey</material>
  </gazebo>

  <!-- JOINT: chassis -->
  <joint name="chassis_joint" type="fixed">
    <origin xyz="0 0 0" rpy="0 0 0"/>
    <parent link="base_footprint"/>
    <child link="chassis"/>
  </joint>

  <!-- JOINT: main_steer -->
  <joint name="main_steer_joint" type="continuous">
    <origin xyz="0.170 0 0.013" rpy="0 0 0"/>
    <parent link="chassis"/>
    <child link="main_steer"/>
    <axis xyz="0 0 1" rpy="0 0 0"/>
    <limit effort="10000" velocity="1000"/>
    <dynamics damping="1.0" friction="1.0"/>
  </joint>

  <!-- JOINT: left_steer -->
  <joint name="left_steer_joint" type="continuous">
    <origin xyz="0.179 0.060 0.013" rpy="0 0 0"/>
    <parent link="chassis"/>
    <child link="left_steer"/>
    <axis xyz="0 0 1" rpy="0 0 0"/>
    <limit effort="10000" velocity="1000"/>
    <dynamics damping="1.0" friction="1.0"/>
  </joint>

  <!-- JOINT: right_steer -->
  <joint name="right_steer_joint" type="continuous">
    <origin xyz="0.179 -0.060 0.013" rpy="0 0 0"/>
    <parent link="chassis"/>
    <child link="right_steer"/>
    <axis xyz="0 0 1" rpy="0 0 0"/>
    <limit effort="10000" velocity="1000"/>
    <dynamics damping="1.0" friction="1.0"/>
  </joint>

  <!-- JOINT: rear_left_tire -->
  <joint name="rear_left_tire_joint" type="continuous">
    <origin xyz="0.024 0.0855 0.015" rpy="-1.570796 0 0"/>
    <parent link="chassis"/>
    <child link="rear_left_tire"/>
    <axis xyz="0 0 1" rpy="0 0 0"/>
    <limit effort="10000" velocity="1000"/>
    <dynamics damping="1.0" friction="1.0"/>
  </joint>

  <!-- JOINT: rear_left_disk -->
  <joint name="rear_left_disk_joint" type="fixed">
    <origin xyz="0 0 0" rpy="-3.141592 0 0"/>
    <parent link="rear_left_tire"/>
    <child link="rear_left_disk"/>
  </joint>

  <!-- JOINT: rear_right_tire -->
  <joint name="rear_right_tire_joint" type="continuous">
    <origin xyz="0.024 -0.0855 0.015" rpy="-1.570796 0 0"/>
    <parent link="chassis"/>
    <child link="rear_right_tire"/>
    <axis xyz="0 0 1" rpy="0 0 0"/>
    <limit effort="10000" velocity="1000"/>
    <dynamics damping="1.0" friction="1.0"/>
  </joint>

  <!-- JOINT: rear_right_disk -->
  <joint name="rear_right_disk_joint" type="fixed">
    <origin xyz="0 0 0" rpy="0 0 0"/>
    <parent link="rear_right_tire"/>
    <child link="rear_right_disk"/>
  </joint>

  <!-- JOINT: front_left_tire -->
  <joint name="front_left_tire_joint" type="continuous">
    <origin xyz="0 0.014 0.002" rpy="1.570796 0 0"/>
    <parent link="left_steer"/>
    <child link="front_left_tire"/>
    <axis xyz="0 0 1" rpy="0 0 0"/>
    <limit effort="10000" velocity="1000"/>
    <dynamics damping="1.0" friction="1.0"/>
  </joint>

  <!-- JOINT: front_left_disk -->
  <joint name="front_left_disk_joint" type="fixed">
    <origin xyz="0 0 0" rpy="-3.141592 0 0"/>
    <parent link="front_left_tire"/>
    <child link="front_left_disk"/>
  </joint>

  <!-- JOINT: front_right_tire -->
  <joint name="front_right_tire_joint" type="continuous">
    <origin xyz="0 -0.014 0.002" rpy="1.570796 0 0"/>
    <parent link="right_steer"/>
    <child link="front_right_tire"/>
    <axis xyz="0 0 1" rpy="0 0 0"/>
    <limit effort="10000" velocity="1000"/>
    <dynamics damping="1.0" friction="1.0"/>
  </joint>

  <!-- JOINT: front_right_disk -->
  <joint name="front_right_disk_joint" type="fixed">
    <origin xyz="0 0 0" rpy="0 0 0"/>
    <parent link="front_right_tire"/>
    <child link="front_right_disk"/>
  </joint>

  <!-- PLUGIN: drive -->
  <gazebo>
    <plugin name="ackermann_drive_controller" filename="libgazebo_ros_ackermann_drive.so">
      <ros>
        <namespace>/car</namespace>
        <argument>/cmd_vel:=cmd_vel</argument>
        <argument>/odom:=odom</argument>
        <argument>/distance:=distance</argument>
      </ros>
      <update_rate>100.0</update_rate>
      <odometry_frame>odom</odometry_frame>
      <robot_base_frame>base_footprint</robot_base_frame>

      <front_left_joint>front_left_tire_joint</front_left_joint>
      <front_right_joint>front_right_tire_joint</front_right_joint>
      <rear_left_joint>rear_left_tire_joint</rear_left_joint>
      <rear_right_joint>rear_right_tire_joint</rear_right_joint>

      <left_steering_joint>left_steer_joint</left_steering_joint>
      <right_steering_joint>right_steer_joint</right_steering_joint>
      <steering_wheel_joint>main_steer_joint</steering_wheel_joint>
      
      <max_steer>0.3</max_steer>
      <max_steering_angle>5.0</max_steering_angle>
      <max_speed>100</max_speed>

      <left_steering_pid_gain>1000 0 1</left_steering_pid_gain>
      <left_steering_i_range>0 0</left_steering_i_range>
      <right_steering_pid_gain>1000 0 1</right_steering_pid_gain>
      <right_steering_i_range>0 0</right_steering_i_range>
      <linear_velocity_pid_gain>10 0 1</linear_velocity_pid_gain>
      <linear_velocity_i_range>0 0</linear_velocity_i_range>

      <publish_odom>true</publish_odom>
      <publish_odom_tf>true</publish_odom_tf>
      <publish_wheel_tf>false</publish_wheel_tf>
      <publish_distance>false</publish_distance>
    </plugin>
  </gazebo>

  <!-- = = = = = = = = = = = = = = = = = = = = = = = = = = = = = = -->

  <!-- LINK: area -->
  <link name="area">
    <inertial>
      <mass value="10"/>
      <inertia ixx="1.0" ixy="0.0" ixz="0.0" iyy="1.0" iyz="0.0" izz="1.0"/>
    </inertial>

    <collision name='area_collision'>
      <origin xyz="0 0 0" rpy="0 0 0"/>
      <geometry>
        <box size="0.42 0.42 0.42"/>
      </geometry>
    </collision>

    <!-- <visual name='area_visual'>
      <origin xyz="0 0 0" rpy="0 0 0"/>
      <geometry>
        <box size="0.42 0.42 0.42"/>
      </geometry>
    </visual> -->
  </link>

  <!-- LINK: x_shaft -->
  <link name="x_shaft">
    <inertial>
      <mass value="0.1"/>
      <inertia ixx="1.0" ixy="0.0" ixz="0.0" iyy="1.0" iyz="0.0" izz="1.0"/>
    </inertial>

    <collision name='x_shaft_collision'>
      <origin xyz="0 0 0" rpy="0 0 0"/>
      <geometry>
        <box size="0.40 0.01 0.01"/>
      </geometry>
    </collision>

    <!-- <visual name='x_shaft_visual'>
      <origin xyz="0 0 0" rpy="0 0 0"/>
      <geometry>
        <box size="0.40 0.01 0.01"/>
      </geometry>
    </visual> -->
  </link>

  <!-- LINK: y_shaft -->
  <link name="y_shaft">
    <inertial>
      <mass value="0.1"/>
      <inertia ixx="1.0" ixy="0.0" ixz="0.0" iyy="1.0" iyz="0.0" izz="1.0"/>
    </inertial>

    <collision name='y_shaft_collision'>
      <origin xyz="0 0 0" rpy="0 0 0"/>
      <geometry>
        <box size="0.01 0.40 0.01"/>
      </geometry>
    </collision>

    <!-- <visual name='y_shaft_visual'>
      <origin xyz="0 0 0" rpy="0 0 0"/>
      <geometry>
        <box size="0.01 0.40 0.01"/>
      </geometry>
    </visual> -->
  </link>

  <!-- LINK: z_shaft -->
  <link name="z_shaft">
    <inertial>
      <mass value="0.1"/>
      <inertia ixx="1.0" ixy="0.0" ixz="0.0" iyy="1.0" iyz="0.0" izz="1.0"/>
    </inertial>

    <collision name='z_shaft_collision'>
      <origin xyz="0 0 0" rpy="0 0 0"/>
      <geometry>
        <box size="0.01 0.01 0.40"/>
      </geometry>
    </collision>

    <!-- <visual name='z_shaft_visual'>
      <origin xyz="0 0 0" rpy="0 0 0"/>
      <geometry>
        <box size="0.01 0.01 0.40"/>
      </geometry>
    </visual> -->
  </link>

  <!-- LINK: camera1 -->
  <link name="camera1">
    <inertial>
      <mass value="0.001"/>
      <inertia ixx="1.0" ixy="0.0" ixz="0.0" iyy="1.0" iyz="0.0" izz="1.0"/>
    </inertial>

    <collision name='camera1_collision'>
      <origin xyz="0 0 0" rpy="0 0 0"/>
      <geometry>
        <box size="0.02 0.02 0.02"/>
      </geometry>
    </collision>

    <visual name='camera1_visual'>
      <origin xyz="0 0 0" rpy="0 0 0"/>
      <geometry>
        <box size="0.02 0.02 0.02"/>
      </geometry>
    </visual>
  </link>

  <!-- COLOR: area -->
  <!-- <gazebo reference="area">
    <material>Gazebo/BlueTransparent</material>
  </gazebo> -->

  <!-- COLOR: x_shaft -->
  <!-- <gazebo reference="x_shaft">
    <material>Gazebo/White</material>
  </gazebo> -->

  <!-- COLOR: y_shaft -->
  <!-- <gazebo reference="y_shaft">
    <material>Gazebo/White</material>
  </gazebo> -->

  <!-- COLOR: z_shaft -->
  <!-- <gazebo reference="z_shaft">
    <material>Gazebo/White</material>
  </gazebo> -->

  <!-- COLOR: camera1 -->
  <gazebo reference="camera1">
    <material>Gazebo/Orange</material>
  </gazebo>

  <!-- JOINT: connection -->
  <joint name="connection_joint" type="fixed">
    <origin xyz="0 0 1" rpy="0 0 -1.5707963"/>
    <parent link="chassis"/>
    <child link="area"/>
  </joint>

  <!-- JOINT: area -->
  <joint name="area_joint" type="fixed">
    <origin xyz="0 0 0" rpy="0 0 0"/>
    <parent link="area"/>
    <child link="x_shaft"/>
  </joint>

  <!-- JOINT: x_joint -->
  <joint name="x_joint" type="prismatic">
    <axis xyz="1 0 0"/>
    <origin xyz="0 0 0" rpy="0 0 0"/>
    <parent link="x_shaft"/>
    <child link="y_shaft"/>
    <limit effort="1000.0" lower="-0.2" upper="0.2" velocity="30"/>
    <dynamics damping="0.0" friction="1.0"/>
  </joint>

  <!-- JOINT: y_joint -->
  <joint name="y_joint" type="prismatic">
    <axis xyz="0 1 0"/>
    <origin xyz="0 0 0" rpy="0 0 0"/>
    <parent link="y_shaft"/>
    <child link="z_shaft"/>
    <limit effort="1000.0" lower="-0.2" upper="0.2" velocity="30"/>
    <dynamics damping="0.0" friction="1.0"/>
  </joint>

  <!-- JOINT: z_joint -->
  <joint name="z_joint" type="prismatic">
    <axis xyz="0 0 1"/>
    <origin xyz="0 0 0" rpy="0 0 1.5707963"/>
    <parent link="z_shaft"/>
    <child link="camera1"/>
    <limit effort="1000.0" lower="-0.2" upper="0.2" velocity="30"/>
    <dynamics damping="0.0" friction="1.0"/>
  </joint>

  <!-- ROS2 CONTROL: GazeboSystem -->
  <ros2_control name="GazeboSystem" type="system">
    <hardware>
      <plugin>gazebo_ros2_control/GazeboSystem</plugin>
    </hardware>

    <joint name="x_joint">
      <command_interface name="position">
        <param name="min">-0.2</param>
        <param name="max">0.2</param>
      </command_interface>
      <state_interface name="position"/>
    </joint>

    <joint name="y_joint">
      <command_interface name="position">
        <param name="min">-0.2</param>
        <param name="max">0.2</param>
      </command_interface>
      <state_interface name="position"/>
    </joint>

    <joint name="z_joint">
      <command_interface name="position">
        <param name="min">-0.2</param>
        <param name="max">0.2</param>
      </command_interface>
      <state_interface name="position"/>
    </joint>
  </ros2_control>

  <!-- PLUGIN: camera_movement -->
  <gazebo>
    <plugin name="camera_movement" filename="libgazebo_ros2_control.so">
      <parameters>$(find sim)/config/camera_movement.yaml</parameters>
    </plugin>
  </gazebo>

  <!-- PLUGIN: camera1 -->
  <gazebo reference="camera1">
    <sensor type="camera" name="camera1">
      <visualize>false</visualize>
      <update_rate>30.0</update_rate>

      <camera name="camera1">
        <horizontal_fov>1.3962634</horizontal_fov>
        <image>
          <width>800</width>
          <height>800</height>
          <format>R8G8B8</format>
        </image>
        <clip>
          <near>0.02</near>
          <far>300</far>
        </clip>
        <distortion>
          <k1>0.0</k1>
          <k2>0.0</k2>
          <k3>0.0</k3>
          <p1>0.0</p1>
          <p2>0.0</p2>
          <center>0.5 0.5</center>
        </distortion>
      </camera>

      <plugin name="camera1_controller" filename="libgazebo_ros_camera.so">
        <always_on>true</always_on>

        <ros>
          <namespace>/car</namespace>
          <argument>camera/image_raw:=/car/camera/image</argument>
          <argument>camera/camera_info:=/car/camera/image/camera_info</argument>
        </ros>
        
        <camera_name>camera1</camera_name>
        <frame_name>base_footprint</frame_name>
        <hack_baseline>0.07</hack_baseline>
      </plugin>
    </sensor>
  </gazebo>

  <!-- = = = = = = = = = = = = = = = = = = = = = = = = = = = = = = -->

  <!-- LINK: car_body -->
  <link name="car_body">
    <pose>0 0 0 0 0 0</pose>

    <inertial>
      <mass value="0.001"/>
      <origin xyz="0 0 0" rpy="0 0 0"/>
      <inertia ixx="0.1" ixy="0" ixz="0" iyy="0.1" iyz="0" izz="0.1"/>
    </inertial>

    <collision name="car_body_collision">
      <origin xyz="0 0 0" rpy="0 0 0"/>
      <geometry>
        <mesh scale="0.03 0.03 0.03" filename="package://sim/meshes/car_body.stl"/>
      </geometry>
    </collision>

    <visual name="car_body_visual">
      <origin xyz="0 0 0" rpy="0 0 0"/>
      <geometry>
        <mesh scale="0.03 0.03 0.03" filename="package://sim/meshes/car_body.stl"/>
      </geometry>
    </visual>
  </link>

  <!-- LINK: car_bottom -->
  <link name="car_bottom">
    <pose>0 0 0 0 0 0</pose>

    <inertial>
      <mass value="0.001"/>
      <origin xyz="0 0 0" rpy="0 0 0"/>
      <inertia ixx="0.1" ixy="0" ixz="0" iyy="0.1" iyz="0" izz="0.1"/>
    </inertial>

    <collision name="car_bottom_collision">
      <origin xyz="0 0 0" rpy="0 0 0"/>
      <geometry>
        <mesh scale="0.03 0.03 0.03" filename="package://sim/meshes/car_bottom.stl"/>
      </geometry>
    </collision>

    <visual name="car_bottom_visual">
      <origin xyz="0 0 0" rpy="0 0 0"/>
      <geometry>
        <mesh scale="0.03 0.03 0.03" filename="package://sim/meshes/car_bottom.stl"/>
      </geometry>
    </visual>
  </link>

  <!-- LINK: car_steering -->
  <link name="car_steering">
    <pose>0 0 0 0 0 0</pose>

    <inertial>
      <mass value="0.001"/>
      <origin xyz="0 0 0" rpy="0 0 0"/>
      <inertia ixx="0.1" ixy="0" ixz="0" iyy="0.1" iyz="0" izz="0.1"/>
    </inertial>

    <collision name="car_steering_collision">
      <origin xyz="0 0 0" rpy="0 0 0"/>
      <geometry>
        <mesh scale="0.03 0.03 0.03" filename="package://sim/meshes/car_steering.stl"/>
      </geometry>
    </collision>

    <visual name="car_steering_visual">
      <origin xyz="0 0 0" rpy="0 0 0"/>
      <geometry>
        <mesh scale="0.03 0.03 0.03" filename="package://sim/meshes/car_steering.stl"/>
      </geometry>
    </visual>
  </link>

  <!-- LINK: fl -->
  <link name="fl">
    <pose>0 0 0 0 0 0</pose>

    <inertial>
      <mass value="0.001"/>
      <origin xyz="0 0 0" rpy="0 0 0"/>
      <inertia ixx="0.1" ixy="0" ixz="0" iyy="0.1" iyz="0" izz="0.1"/>
    </inertial>

    <collision name="fl_collision">
      <origin xyz="0 0 0" rpy="0 0 0"/>
      <geometry>
        <mesh scale="0.03 0.03 0.03" filename="package://sim/meshes/car_wheel.stl"/>
      </geometry>
    </collision>

    <visual name="fl_visual">
      <origin xyz="0 0 0" rpy="0 0 0"/>
      <geometry>
        <mesh scale="0.03 0.03 0.03" filename="package://sim/meshes/car_wheel.stl"/>
      </geometry>
    </visual>
  </link>

  <!-- LINK: fr -->
  <link name="fr">
    <pose>0 0 0 0 0 0</pose>

    <inertial>
      <mass value="0.001"/>
      <origin xyz="0 0 0" rpy="0 0 0"/>
      <inertia ixx="0.1" ixy="0" ixz="0" iyy="0.1" iyz="0" izz="0.1"/>
    </inertial>

    <collision name="fr_collision">
      <origin xyz="0 0 0" rpy="0 0 0"/>
      <geometry>
        <mesh scale="0.03 0.03 0.03" filename="package://sim/meshes/car_wheel.stl"/>
      </geometry>
    </collision>

    <visual name="fr_visual">
      <origin xyz="0 0 0" rpy="0 0 0"/>
      <geometry>
        <mesh scale="0.03 0.03 0.03" filename="package://sim/meshes/car_wheel.stl"/>
      </geometry>
    </visual>
  </link>

  <!-- LINK: rl -->
  <link name="rl">
    <pose>0 0 0 0 0 0</pose>

    <inertial>
      <mass value="0.001"/>
      <origin xyz="0 0 0" rpy="0 0 0"/>
      <inertia ixx="0.1" ixy="0" ixz="0" iyy="0.1" iyz="0" izz="0.1"/>
    </inertial>

    <collision name="rl_collision">
      <origin xyz="0 0 0" rpy="0 0 0"/>
      <geometry>
        <mesh scale="0.03 0.03 0.03" filename="package://sim/meshes/car_wheel.stl"/>
      </geometry>
    </collision>

    <visual name="rl_visual">
      <origin xyz="0 0 0" rpy="0 0 0"/>
      <geometry>
        <mesh scale="0.03 0.03 0.03" filename="package://sim/meshes/car_wheel.stl"/>
      </geometry>
    </visual>
  </link>

  <!-- LINK: rr -->
  <link name="rr">
    <pose>0 0 0 0 0 0</pose>

    <inertial>
      <mass value="0.001"/>
      <origin xyz="0 0 0" rpy="0 0 0"/>
      <inertia ixx="0.1" ixy="0" ixz="0" iyy="0.1" iyz="0" izz="0.1"/>
    </inertial>

    <collision name="rr_collision">
      <origin xyz="0 0 0" rpy="0 0 0"/>
      <geometry>
        <mesh scale="0.03 0.03 0.03" filename="package://sim/meshes/car_wheel.stl"/>
      </geometry>
    </collision>

    <visual name="rr_visual">
      <origin xyz="0 0 0" rpy="0 0 0"/>
      <geometry>
        <mesh scale="0.03 0.03 0.03" filename="package://sim/meshes/car_wheel.stl"/>
      </geometry>
    </visual>
  </link>

  <!-- COLOR: car_body -->
  <gazebo reference="car_body">
    <material>Gazebo/Orange</material>
  </gazebo>

  <!-- COLOR: car_bottom -->
  <gazebo reference="car_bottom">
    <material>Gazebo/Grey</material>
  </gazebo>

  <!-- COLOR: car_steering -->
  <gazebo reference="car_steering">
    <material>Gazebo/White</material>
  </gazebo>

  <!-- COLOR: fl -->
  <gazebo reference="fl">
    <material>Gazebo/Grey</material>
  </gazebo>

  <!-- COLOR: fr -->
  <gazebo reference="fr">
    <material>Gazebo/Grey</material>
  </gazebo>

  <!-- COLOR: rl -->
  <gazebo reference="rl">
    <material>Gazebo/Grey</material>
  </gazebo>

  <!-- COLOR: rr -->
  <gazebo reference="rr">
    <material>Gazebo/Grey</material>
  </gazebo>

  <!-- JOINT: car_body -->
  <joint name="car_body_joint" type="fixed">
    <origin xyz="0 0 0" rpy="0 0 -1.570796"/>
    <parent link="chassis"/>
    <child link="car_body"/>
  </joint>

  <!-- JOINT: car_bottom -->
  <joint name="car_bottom_joint" type="fixed">
    <origin xyz="0 -0.58 0.6" rpy="0 0 -1.570796"/>
    <parent link="chassis"/>
    <child link="car_bottom"/>
  </joint>

  <!-- JOINT: car_steering -->
  <joint name="car_steering_joint" type="fixed">
    <origin xyz="0.26 0.26 0.8" rpy="0 -1.570796 3.141592"/>
    <parent link="chassis"/>
    <child link="car_steering"/>
  </joint>

  <!-- JOINT: fl -->
  <joint name="fl_joint" type="fixed">
    <origin xyz="0.88 0.65 0.25" rpy="-1.570796 0 0"/>
    <parent link="chassis"/>
    <child link="fl"/>
  </joint>

  <!-- JOINT: fr -->
  <joint name="fr_joint" type="fixed">
    <origin xyz="0.88 -0.65 0.25" rpy="1.570796 0 0"/>
    <parent link="chassis"/>
    <child link="fr"/>
  </joint>

  <!-- JOINT: rl -->
  <joint name="rl_joint" type="fixed">
    <origin xyz="-0.73 0.65 0.25" rpy="-1.570796 0 0"/>
    <parent link="chassis"/>
    <child link="rl"/>
  </joint>

  <!-- JOINT: rr -->
  <joint name="rr_joint" type="fixed">
    <origin xyz="-0.73 -0.65 0.25" rpy="1.570796 0 0"/>
    <parent link="chassis"/>
    <child link="rr"/>
  </joint>
</robot>